============`finance_datareader.py`============
2025-10-01 18:46:45.199507
0.9.96
Traceback (most recent call last):
  File "/home/sese/venv/lib/python3.12/site-packages/urllib3/connection.py", line 198, in _new_conn
    sock = connection.create_connection(
           ^^^^^^^^^^^^^^^^^^^^^^^^^^^^^
  File "/home/sese/venv/lib/python3.12/site-packages/urllib3/util/connection.py", line 85, in create_connection
    raise err
  File "/home/sese/venv/lib/python3.12/site-packages/urllib3/util/connection.py", line 73, in create_connection
    sock.connect(sa)
TimeoutError: [Errno 110] Connection timed out

The above exception was the direct cause of the following exception:

Traceback (most recent call last):
  File "/home/sese/venv/lib/python3.12/site-packages/urllib3/connectionpool.py", line 787, in urlopen
    response = self._make_request(
               ^^^^^^^^^^^^^^^^^^^
  File "/home/sese/venv/lib/python3.12/site-packages/urllib3/connectionpool.py", line 493, in _make_request
    conn.request(
  File "/home/sese/venv/lib/python3.12/site-packages/urllib3/connection.py", line 494, in request
    self.endheaders()
  File "/usr/lib/python3.12/http/client.py", line 1331, in endheaders
    self._send_output(message_body, encode_chunked=encode_chunked)
  File "/usr/lib/python3.12/http/client.py", line 1091, in _send_output
    self.send(msg)
  File "/usr/lib/python3.12/http/client.py", line 1035, in send
    self.connect()
  File "/home/sese/venv/lib/python3.12/site-packages/urllib3/connection.py", line 325, in connect
    self.sock = self._new_conn()
                ^^^^^^^^^^^^^^^^
  File "/home/sese/venv/lib/python3.12/site-packages/urllib3/connection.py", line 207, in _new_conn
    raise ConnectTimeoutError(
urllib3.exceptions.ConnectTimeoutError: (<urllib3.connection.HTTPConnection object at 0x7fb3fc5a0ec0>, 'Connection to data.krx.co.kr timed out. (connect timeout=None)')

The above exception was the direct cause of the following exception:

Traceback (most recent call last):
  File "/home/sese/venv/lib/python3.12/site-packages/requests/adapters.py", line 644, in send
    resp = conn.urlopen(
           ^^^^^^^^^^^^^
  File "/home/sese/venv/lib/python3.12/site-packages/urllib3/connectionpool.py", line 841, in urlopen
    retries = retries.increment(
              ^^^^^^^^^^^^^^^^^^
  File "/home/sese/venv/lib/python3.12/site-packages/urllib3/util/retry.py", line 519, in increment
    raise MaxRetryError(_pool, url, reason) from reason  # type: ignore[arg-type]
    ^^^^^^^^^^^^^^^^^^^^^^^^^^^^^^^^^^^^^^^^^^^^^^^^^^^
urllib3.exceptions.MaxRetryError: HTTPConnectionPool(host='data.krx.co.kr', port=80): Max retries exceeded with url: /comm/bldAttendant/getJsonData.cmd (Caused by ConnectTimeoutError(<urllib3.connection.HTTPConnection object at 0x7fb3fc5a0ec0>, 'Connection to data.krx.co.kr timed out. (connect timeout=None)'))

During handling of the above exception, another exception occurred:

Traceback (most recent call last):
  File "/home/sese/data_pipeline/utils/finance_datareader.py", line 8, in <module>
    df = fdr.DataReader('KS11', '2020') 
         ^^^^^^^^^^^^^^^^^^^^^^^^^^^^^^
  File "/home/sese/venv/lib/python3.12/site-packages/FinanceDataReader/data.py", line 67, in DataReader
    return KrxIndexReader(symbol, start, end).read()
           ^^^^^^^^^^^^^^^^^^^^^^^^^^^^^^^^^^^^^^^^^
  File "/home/sese/venv/lib/python3.12/site-packages/FinanceDataReader/krx/data.py", line 273, in read
    df = _krx_index_price(idx1, idx2, self.start, self.end)
         ^^^^^^^^^^^^^^^^^^^^^^^^^^^^^^^^^^^^^^^^^^^^^^^^^^
  File "/home/sese/venv/lib/python3.12/site-packages/FinanceDataReader/krx/data.py", line 64, in _krx_index_price
    df = _krx_index_price_2years(idx1, idx2, _start, _end)
         ^^^^^^^^^^^^^^^^^^^^^^^^^^^^^^^^^^^^^^^^^^^^^^^^^
  File "/home/sese/venv/lib/python3.12/site-packages/FinanceDataReader/krx/data.py", line 47, in _krx_index_price_2years
    r = requests.post(url, data, headers=headers)
        ^^^^^^^^^^^^^^^^^^^^^^^^^^^^^^^^^^^^^^^^^
  File "/home/sese/venv/lib/python3.12/site-packages/requests/api.py", line 115, in post
    return request("post", url, data=data, json=json, **kwargs)
           ^^^^^^^^^^^^^^^^^^^^^^^^^^^^^^^^^^^^^^^^^^^^^^^^^^^^
  File "/home/sese/venv/lib/python3.12/site-packages/requests/api.py", line 59, in request
    return session.request(method=method, url=url, **kwargs)
           ^^^^^^^^^^^^^^^^^^^^^^^^^^^^^^^^^^^^^^^^^^^^^^^^^
  File "/home/sese/venv/lib/python3.12/site-packages/requests/sessions.py", line 589, in request
    resp = self.send(prep, **send_kwargs)
           ^^^^^^^^^^^^^^^^^^^^^^^^^^^^^^
  File "/home/sese/venv/lib/python3.12/site-packages/requests/sessions.py", line 703, in send
    r = adapter.send(request, **kwargs)
        ^^^^^^^^^^^^^^^^^^^^^^^^^^^^^^^
  File "/home/sese/venv/lib/python3.12/site-packages/requests/adapters.py", line 665, in send
    raise ConnectTimeout(e, request=request)
requests.exceptions.ConnectTimeout: HTTPConnectionPool(host='data.krx.co.kr', port=80): Max retries exceeded with url: /comm/bldAttendant/getJsonData.cmd (Caused by ConnectTimeoutError(<urllib3.connection.HTTPConnection object at 0x7fb3fc5a0ec0>, 'Connection to data.krx.co.kr timed out. (connect timeout=None)'))
